[2023-07-28 22:48:00,953] {taskinstance.py:1179} INFO - Dependencies all met for <TaskInstance: dag_etl_paises.obtener_datos manual__2023-07-28T22:47:26.096102+00:00 [queued]>
[2023-07-28 22:48:01,134] {taskinstance.py:1179} INFO - Dependencies all met for <TaskInstance: dag_etl_paises.obtener_datos manual__2023-07-28T22:47:26.096102+00:00 [queued]>
[2023-07-28 22:48:01,136] {taskinstance.py:1376} INFO - 
--------------------------------------------------------------------------------
[2023-07-28 22:48:01,140] {taskinstance.py:1377} INFO - Starting attempt 1 of 2
[2023-07-28 22:48:01,148] {taskinstance.py:1378} INFO - 
--------------------------------------------------------------------------------
[2023-07-28 22:48:01,372] {taskinstance.py:1397} INFO - Executing <Task(PythonOperator): obtener_datos> on 2023-07-28 22:47:26.096102+00:00
[2023-07-28 22:48:01,442] {standard_task_runner.py:52} INFO - Started process 393 to run task
[2023-07-28 22:48:01,537] {standard_task_runner.py:79} INFO - Running: ['***', 'tasks', 'run', 'dag_etl_paises', 'obtener_datos', 'manual__2023-07-28T22:47:26.096102+00:00', '--job-id', '11', '--raw', '--subdir', 'DAGS_FOLDER/dag_etl_paises.py', '--cfg-path', '/tmp/tmpft77yka_', '--error-file', '/tmp/tmppi388jrr']
[2023-07-28 22:48:01,662] {standard_task_runner.py:80} INFO - Job 11: Subtask obtener_datos
[2023-07-28 22:48:03,397] {task_command.py:371} INFO - Running <TaskInstance: dag_etl_paises.obtener_datos manual__2023-07-28T22:47:26.096102+00:00 [running]> on host 24fcae152ca2
[2023-07-28 22:48:06,003] {taskinstance.py:1591} INFO - Exporting the following env vars:
AIRFLOW_CTX_DAG_OWNER=Belenpintor
AIRFLOW_CTX_DAG_ID=dag_etl_paises
AIRFLOW_CTX_TASK_ID=obtener_datos
AIRFLOW_CTX_EXECUTION_DATE=2023-07-28T22:47:26.096102+00:00
AIRFLOW_CTX_TRY_NUMBER=1
AIRFLOW_CTX_DAG_RUN_ID=manual__2023-07-28T22:47:26.096102+00:00
[2023-07-28 22:49:14,173] {local_task_job.py:84} ERROR - Received SIGTERM. Terminating subprocesses
[2023-07-28 22:49:15,108] {process_utils.py:129} INFO - Sending Signals.SIGTERM to group 393. PIDs of all processes in the group: [393]
[2023-07-28 22:49:15,155] {process_utils.py:80} INFO - Sending the signal Signals.SIGTERM to group 393
[2023-07-28 22:49:15,623] {taskinstance.py:1561} ERROR - Received SIGTERM. Terminating subprocesses.
[2023-07-28 22:49:17,430] {taskinstance.py:1909} ERROR - Task failed with exception
Traceback (most recent call last):
  File "/home/airflow/.local/lib/python3.7/site-packages/airflow/operators/python.py", line 171, in execute
    return_value = self.execute_callable()
  File "/home/airflow/.local/lib/python3.7/site-packages/airflow/operators/python.py", line 189, in execute_callable
    return self.python_callable(*self.op_args, **self.op_kwargs)
  File "/opt/airflow/dags/script_etl.py", line 52, in get_data
    response = requests.get(ciudad_url)
  File "/home/airflow/.local/lib/python3.7/site-packages/requests/api.py", line 73, in get
    return request("get", url, params=params, **kwargs)
  File "/home/airflow/.local/lib/python3.7/site-packages/requests/api.py", line 59, in request
    return session.request(method=method, url=url, **kwargs)
  File "/home/airflow/.local/lib/python3.7/site-packages/requests/sessions.py", line 587, in request
    resp = self.send(prep, **send_kwargs)
  File "/home/airflow/.local/lib/python3.7/site-packages/requests/sessions.py", line 701, in send
    r = adapter.send(request, **kwargs)
  File "/home/airflow/.local/lib/python3.7/site-packages/requests/adapters.py", line 499, in send
    timeout=timeout,
  File "/home/airflow/.local/lib/python3.7/site-packages/urllib3/connectionpool.py", line 710, in urlopen
    chunked=chunked,
  File "/home/airflow/.local/lib/python3.7/site-packages/urllib3/connectionpool.py", line 386, in _make_request
    self._validate_conn(conn)
  File "/home/airflow/.local/lib/python3.7/site-packages/urllib3/connectionpool.py", line 1040, in _validate_conn
    conn.connect()
  File "/home/airflow/.local/lib/python3.7/site-packages/urllib3/connection.py", line 424, in connect
    tls_in_tls=tls_in_tls,
  File "/home/airflow/.local/lib/python3.7/site-packages/urllib3/util/ssl_.py", line 450, in ssl_wrap_socket
    sock, context, tls_in_tls, server_hostname=server_hostname
  File "/home/airflow/.local/lib/python3.7/site-packages/urllib3/util/ssl_.py", line 493, in _ssl_wrap_socket_impl
    return ssl_context.wrap_socket(sock, server_hostname=server_hostname)
  File "/usr/local/lib/python3.7/ssl.py", line 423, in wrap_socket
    session=session
  File "/usr/local/lib/python3.7/ssl.py", line 870, in _create
    self.do_handshake()
  File "/usr/local/lib/python3.7/ssl.py", line 1139, in do_handshake
    self._sslobj.do_handshake()
  File "/home/airflow/.local/lib/python3.7/site-packages/airflow/models/taskinstance.py", line 1563, in signal_handler
    raise AirflowException("Task received SIGTERM signal")
airflow.exceptions.AirflowException: Task received SIGTERM signal
[2023-07-28 22:49:17,812] {taskinstance.py:1420} INFO - Marking task as UP_FOR_RETRY. dag_id=dag_etl_paises, task_id=obtener_datos, execution_date=20230728T224726, start_date=20230728T224800, end_date=20230728T224917
[2023-07-28 22:49:18,182] {standard_task_runner.py:97} ERROR - Failed to execute job 11 for task obtener_datos (Task received SIGTERM signal; 393)
[2023-07-28 22:49:18,457] {process_utils.py:75} INFO - Process psutil.Process(pid=393, status='terminated', exitcode=1, started='22:48:00') (393) terminated with exit code 1
[2023-07-28 22:49:18,460] {local_task_job.py:156} INFO - Task exited with return code 143
[2023-07-28 22:49:19,360] {local_task_job.py:273} INFO - 0 downstream tasks scheduled from follow-on schedule check
