[2023-07-28 23:16:51,280] {taskinstance.py:1179} INFO - Dependencies all met for <TaskInstance: dag_etl_paises.enviar_fallo manual__2023-07-28T23:15:38.751579+00:00 [queued]>
[2023-07-28 23:16:51,319] {taskinstance.py:1179} INFO - Dependencies all met for <TaskInstance: dag_etl_paises.enviar_fallo manual__2023-07-28T23:15:38.751579+00:00 [queued]>
[2023-07-28 23:16:51,321] {taskinstance.py:1376} INFO - 
--------------------------------------------------------------------------------
[2023-07-28 23:16:51,323] {taskinstance.py:1377} INFO - Starting attempt 2 of 2
[2023-07-28 23:16:51,325] {taskinstance.py:1378} INFO - 
--------------------------------------------------------------------------------
[2023-07-28 23:16:51,385] {taskinstance.py:1397} INFO - Executing <Task(PythonOperator): enviar_fallo> on 2023-07-28 23:15:38.751579+00:00
[2023-07-28 23:16:51,413] {standard_task_runner.py:52} INFO - Started process 444 to run task
[2023-07-28 23:16:51,499] {standard_task_runner.py:79} INFO - Running: ['***', 'tasks', 'run', 'dag_etl_paises', 'enviar_fallo', 'manual__2023-07-28T23:15:38.751579+00:00', '--job-id', '29', '--raw', '--subdir', 'DAGS_FOLDER/dag_etl_paises.py', '--cfg-path', '/tmp/tmpsey69qxk', '--error-file', '/tmp/tmpad0k7zev']
[2023-07-28 23:16:51,528] {standard_task_runner.py:80} INFO - Job 29: Subtask enviar_fallo
[2023-07-28 23:16:52,058] {task_command.py:371} INFO - Running <TaskInstance: dag_etl_paises.enviar_fallo manual__2023-07-28T23:15:38.751579+00:00 [running]> on host 068a3bc06d1c
[2023-07-28 23:16:52,428] {taskinstance.py:1591} INFO - Exporting the following env vars:
AIRFLOW_CTX_DAG_OWNER=Belenpintor
AIRFLOW_CTX_DAG_ID=dag_etl_paises
AIRFLOW_CTX_TASK_ID=enviar_fallo
AIRFLOW_CTX_EXECUTION_DATE=2023-07-28T23:15:38.751579+00:00
AIRFLOW_CTX_TRY_NUMBER=2
AIRFLOW_CTX_DAG_RUN_ID=manual__2023-07-28T23:15:38.751579+00:00
[2023-07-28 23:16:52,504] {logging_mixin.py:115} INFO - [Errno -2] Name or service not known
[2023-07-28 23:16:52,506] {logging_mixin.py:115} INFO - Failure
[2023-07-28 23:16:52,508] {taskinstance.py:1909} ERROR - Task failed with exception
Traceback (most recent call last):
  File "/home/airflow/.local/lib/python3.7/site-packages/airflow/operators/python.py", line 171, in execute
    return_value = self.execute_callable()
  File "/home/airflow/.local/lib/python3.7/site-packages/airflow/operators/python.py", line 189, in execute_callable
    return self.python_callable(*self.op_args, **self.op_kwargs)
  File "/opt/airflow/dags/script_etl.py", line 116, in enviar_fallo
    raise exception
  File "/opt/airflow/dags/script_etl.py", line 105, in enviar_fallo
    x=smtplib.SMTP(Variable.get("SMTP_HOST"),Variable.get("SMTP_PORT"))
  File "/usr/local/lib/python3.7/smtplib.py", line 251, in __init__
    (code, msg) = self.connect(host, port)
  File "/usr/local/lib/python3.7/smtplib.py", line 336, in connect
    self.sock = self._get_socket(host, port, self.timeout)
  File "/usr/local/lib/python3.7/smtplib.py", line 307, in _get_socket
    self.source_address)
  File "/usr/local/lib/python3.7/socket.py", line 707, in create_connection
    for res in getaddrinfo(host, port, 0, SOCK_STREAM):
  File "/usr/local/lib/python3.7/socket.py", line 752, in getaddrinfo
    for res in _socket.getaddrinfo(host, port, family, type, proto, flags):
socket.gaierror: [Errno -2] Name or service not known
[2023-07-28 23:16:52,529] {taskinstance.py:1420} INFO - Marking task as FAILED. dag_id=dag_etl_paises, task_id=enviar_fallo, execution_date=20230728T231538, start_date=20230728T231651, end_date=20230728T231652
[2023-07-28 23:16:52,555] {standard_task_runner.py:97} ERROR - Failed to execute job 29 for task enviar_fallo ([Errno -2] Name or service not known; 444)
[2023-07-28 23:16:52,613] {local_task_job.py:156} INFO - Task exited with return code 1
[2023-07-28 23:16:52,708] {local_task_job.py:273} INFO - 0 downstream tasks scheduled from follow-on schedule check
