[2023-07-12 05:29:47,398] {taskinstance.py:1179} INFO - Dependencies all met for <TaskInstance: dag_con_conexion_postgres.crear_tabla scheduled__2023-07-11T00:00:00+00:00 [queued]>
[2023-07-12 05:29:47,462] {taskinstance.py:1179} INFO - Dependencies all met for <TaskInstance: dag_con_conexion_postgres.crear_tabla scheduled__2023-07-11T00:00:00+00:00 [queued]>
[2023-07-12 05:29:47,463] {taskinstance.py:1376} INFO - 
--------------------------------------------------------------------------------
[2023-07-12 05:29:47,466] {taskinstance.py:1377} INFO - Starting attempt 1 of 1
[2023-07-12 05:29:47,468] {taskinstance.py:1378} INFO - 
--------------------------------------------------------------------------------
[2023-07-12 05:29:47,652] {taskinstance.py:1397} INFO - Executing <Task(PythonOperator): crear_tabla> on 2023-07-11 00:00:00+00:00
[2023-07-12 05:29:47,729] {standard_task_runner.py:52} INFO - Started process 420 to run task
[2023-07-12 05:29:47,837] {standard_task_runner.py:79} INFO - Running: ['***', 'tasks', 'run', 'dag_con_conexion_postgres', 'crear_tabla', 'scheduled__2023-07-11T00:00:00+00:00', '--job-id', '12', '--raw', '--subdir', 'DAGS_FOLDER/dag_etl_paises.py', '--cfg-path', '/tmp/tmp2dkkde5m', '--error-file', '/tmp/tmpbpbmqjrd']
[2023-07-12 05:29:47,856] {standard_task_runner.py:80} INFO - Job 12: Subtask crear_tabla
[2023-07-12 05:29:48,675] {task_command.py:371} INFO - Running <TaskInstance: dag_con_conexion_postgres.crear_tabla scheduled__2023-07-11T00:00:00+00:00 [running]> on host 477ff5c75a8d
[2023-07-12 05:29:56,071] {taskinstance.py:1591} INFO - Exporting the following env vars:
AIRFLOW_CTX_DAG_OWNER=Belenpintor
AIRFLOW_CTX_DAG_ID=dag_con_conexion_postgres
AIRFLOW_CTX_TASK_ID=crear_tabla
AIRFLOW_CTX_EXECUTION_DATE=2023-07-11T00:00:00+00:00
AIRFLOW_CTX_TRY_NUMBER=1
AIRFLOW_CTX_DAG_RUN_ID=scheduled__2023-07-11T00:00:00+00:00
[2023-07-12 05:29:56,077] {taskinstance.py:1909} ERROR - Task failed with exception
Traceback (most recent call last):
  File "/home/airflow/.local/lib/python3.7/site-packages/airflow/operators/python.py", line 171, in execute
    return_value = self.execute_callable()
  File "/home/airflow/.local/lib/python3.7/site-packages/airflow/operators/python.py", line 189, in execute_callable
    return self.python_callable(*self.op_args, **self.op_kwargs)
  File "/opt/airflow/dags/script_etl.py", line 27, in create_table
    connection = create_connection()
  File "/opt/airflow/dags/script_etl.py", line 22, in create_connection
    database=db_database
  File "/home/airflow/.local/lib/python3.7/site-packages/psycopg2/__init__.py", line 122, in connect
    conn = _connect(dsn, connection_factory=connection_factory, **kwasync)
psycopg2.OperationalError: connection to server on socket "/var/run/postgresql/.s.PGSQL.5432" failed: No such file or directory
	Is the server running locally and accepting connections on that socket?

[2023-07-12 05:29:56,186] {taskinstance.py:1420} INFO - Marking task as FAILED. dag_id=dag_con_conexion_postgres, task_id=crear_tabla, execution_date=20230711T000000, start_date=20230712T052947, end_date=20230712T052956
[2023-07-12 05:29:56,321] {standard_task_runner.py:97} ERROR - Failed to execute job 12 for task crear_tabla (connection to server on socket "/var/run/postgresql/.s.PGSQL.5432" failed: No such file or directory
	Is the server running locally and accepting connections on that socket?
; 420)
[2023-07-12 05:29:56,435] {local_task_job.py:156} INFO - Task exited with return code 1
[2023-07-12 05:29:58,048] {local_task_job.py:273} INFO - 0 downstream tasks scheduled from follow-on schedule check
[2023-07-13 16:40:20,956] {taskinstance.py:1179} INFO - Dependencies all met for <TaskInstance: dag_con_conexion_postgres.crear_tabla scheduled__2023-07-11T00:00:00+00:00 [queued]>
[2023-07-13 16:40:21,452] {taskinstance.py:1179} INFO - Dependencies all met for <TaskInstance: dag_con_conexion_postgres.crear_tabla scheduled__2023-07-11T00:00:00+00:00 [queued]>
[2023-07-13 16:40:21,495] {taskinstance.py:1376} INFO - 
--------------------------------------------------------------------------------
[2023-07-13 16:40:21,500] {taskinstance.py:1377} INFO - Starting attempt 1 of 1
[2023-07-13 16:40:21,515] {taskinstance.py:1378} INFO - 
--------------------------------------------------------------------------------
[2023-07-13 16:40:21,891] {taskinstance.py:1397} INFO - Executing <Task(PythonOperator): crear_tabla> on 2023-07-11 00:00:00+00:00
[2023-07-13 16:40:21,950] {standard_task_runner.py:52} INFO - Started process 286 to run task
[2023-07-13 16:40:22,035] {standard_task_runner.py:79} INFO - Running: ['***', 'tasks', 'run', 'dag_con_conexion_postgres', 'crear_tabla', 'scheduled__2023-07-11T00:00:00+00:00', '--job-id', '19', '--raw', '--subdir', 'DAGS_FOLDER/dag_etl_paises.py', '--cfg-path', '/tmp/tmpe1_m0d9t', '--error-file', '/tmp/tmprzi6tmav']
[2023-07-13 16:40:22,046] {standard_task_runner.py:80} INFO - Job 19: Subtask crear_tabla
[2023-07-13 16:40:25,693] {task_command.py:371} INFO - Running <TaskInstance: dag_con_conexion_postgres.crear_tabla scheduled__2023-07-11T00:00:00+00:00 [running]> on host bd4a51b00e09
[2023-07-13 16:40:40,172] {taskinstance.py:1591} INFO - Exporting the following env vars:
AIRFLOW_CTX_DAG_OWNER=Belenpintor
AIRFLOW_CTX_DAG_ID=dag_con_conexion_postgres
AIRFLOW_CTX_TASK_ID=crear_tabla
AIRFLOW_CTX_EXECUTION_DATE=2023-07-11T00:00:00+00:00
AIRFLOW_CTX_TRY_NUMBER=1
AIRFLOW_CTX_DAG_RUN_ID=scheduled__2023-07-11T00:00:00+00:00
[2023-07-13 16:40:40,206] {logging_mixin.py:115} INFO - creando conexion
[2023-07-13 16:40:40,225] {script_etl.py:20} INFO - DB_USER probando usuario 1: None
[2023-07-13 16:40:40,229] {logging_mixin.py:115} INFO - usuario probando 1 None
[2023-07-13 16:40:40,262] {taskinstance.py:1909} ERROR - Task failed with exception
Traceback (most recent call last):
  File "/home/airflow/.local/lib/python3.7/site-packages/airflow/operators/python.py", line 171, in execute
    return_value = self.execute_callable()
  File "/home/airflow/.local/lib/python3.7/site-packages/airflow/operators/python.py", line 189, in execute_callable
    return self.python_callable(*self.op_args, **self.op_kwargs)
  File "/opt/airflow/dags/script_etl.py", line 34, in create_table
    connection = create_connection()
  File "/opt/airflow/dags/script_etl.py", line 29, in create_connection
    database=db_database
  File "/home/airflow/.local/lib/python3.7/site-packages/psycopg2/__init__.py", line 122, in connect
    conn = _connect(dsn, connection_factory=connection_factory, **kwasync)
psycopg2.OperationalError: connection to server on socket "/var/run/postgresql/.s.PGSQL.5432" failed: No such file or directory
	Is the server running locally and accepting connections on that socket?

[2023-07-13 16:40:41,118] {taskinstance.py:1420} INFO - Marking task as FAILED. dag_id=dag_con_conexion_postgres, task_id=crear_tabla, execution_date=20230711T000000, start_date=20230713T164021, end_date=20230713T164041
[2023-07-13 16:40:41,737] {standard_task_runner.py:97} ERROR - Failed to execute job 19 for task crear_tabla (connection to server on socket "/var/run/postgresql/.s.PGSQL.5432" failed: No such file or directory
	Is the server running locally and accepting connections on that socket?
; 286)
[2023-07-13 16:40:42,381] {local_task_job.py:156} INFO - Task exited with return code 1
[2023-07-13 16:40:43,383] {local_task_job.py:273} INFO - 0 downstream tasks scheduled from follow-on schedule check
[2023-07-13 16:58:55,910] {taskinstance.py:1179} INFO - Dependencies all met for <TaskInstance: dag_con_conexion_postgres.crear_tabla scheduled__2023-07-11T00:00:00+00:00 [queued]>
[2023-07-13 16:58:56,351] {taskinstance.py:1179} INFO - Dependencies all met for <TaskInstance: dag_con_conexion_postgres.crear_tabla scheduled__2023-07-11T00:00:00+00:00 [queued]>
[2023-07-13 16:58:56,359] {taskinstance.py:1376} INFO - 
--------------------------------------------------------------------------------
[2023-07-13 16:58:56,385] {taskinstance.py:1377} INFO - Starting attempt 1 of 1
[2023-07-13 16:58:56,403] {taskinstance.py:1378} INFO - 
--------------------------------------------------------------------------------
[2023-07-13 16:58:56,699] {taskinstance.py:1397} INFO - Executing <Task(PythonOperator): crear_tabla> on 2023-07-11 00:00:00+00:00
[2023-07-13 16:58:56,745] {standard_task_runner.py:52} INFO - Started process 809 to run task
[2023-07-13 16:58:56,823] {standard_task_runner.py:79} INFO - Running: ['***', 'tasks', 'run', 'dag_con_conexion_postgres', 'crear_tabla', 'scheduled__2023-07-11T00:00:00+00:00', '--job-id', '24', '--raw', '--subdir', 'DAGS_FOLDER/dag_etl_paises.py', '--cfg-path', '/tmp/tmp9igly2tt', '--error-file', '/tmp/tmpj4qr7y09']
[2023-07-13 16:58:56,831] {standard_task_runner.py:80} INFO - Job 24: Subtask crear_tabla
[2023-07-13 16:58:58,606] {task_command.py:371} INFO - Running <TaskInstance: dag_con_conexion_postgres.crear_tabla scheduled__2023-07-11T00:00:00+00:00 [running]> on host bd4a51b00e09
[2023-07-13 16:59:27,867] {taskinstance.py:1591} INFO - Exporting the following env vars:
AIRFLOW_CTX_DAG_OWNER=Belenpintor
AIRFLOW_CTX_DAG_ID=dag_con_conexion_postgres
AIRFLOW_CTX_TASK_ID=crear_tabla
AIRFLOW_CTX_EXECUTION_DATE=2023-07-11T00:00:00+00:00
AIRFLOW_CTX_TRY_NUMBER=1
AIRFLOW_CTX_DAG_RUN_ID=scheduled__2023-07-11T00:00:00+00:00
[2023-07-13 16:59:27,874] {logging_mixin.py:115} INFO - creando conexion
[2023-07-13 16:59:28,606] {script_etl.py:20} INFO - DB_USER probando usuario 2: bapintor_coderhouse
[2023-07-13 16:59:28,620] {logging_mixin.py:115} INFO - usuario probando 2 bapintor_coderhouse
[2023-07-13 16:59:30,397] {python.py:173} INFO - Done. Returned value was: None
[2023-07-13 16:59:30,796] {taskinstance.py:1420} INFO - Marking task as SUCCESS. dag_id=dag_con_conexion_postgres, task_id=crear_tabla, execution_date=20230711T000000, start_date=20230713T165855, end_date=20230713T165930
[2023-07-13 16:59:31,490] {local_task_job.py:156} INFO - Task exited with return code 0
[2023-07-13 16:59:32,208] {local_task_job.py:273} INFO - 1 downstream tasks scheduled from follow-on schedule check
