[2023-07-25 21:45:24,233] {taskinstance.py:1179} INFO - Dependencies all met for <TaskInstance: dag_con_conexion_postgres.crear_tabla scheduled__2023-07-23T00:00:00+00:00 [queued]>
[2023-07-25 21:45:24,299] {taskinstance.py:1179} INFO - Dependencies all met for <TaskInstance: dag_con_conexion_postgres.crear_tabla scheduled__2023-07-23T00:00:00+00:00 [queued]>
[2023-07-25 21:45:24,301] {taskinstance.py:1376} INFO - 
--------------------------------------------------------------------------------
[2023-07-25 21:45:24,303] {taskinstance.py:1377} INFO - Starting attempt 1 of 1
[2023-07-25 21:45:24,312] {taskinstance.py:1378} INFO - 
--------------------------------------------------------------------------------
[2023-07-25 21:45:24,555] {taskinstance.py:1397} INFO - Executing <Task(PythonOperator): crear_tabla> on 2023-07-23 00:00:00+00:00
[2023-07-25 21:45:24,580] {standard_task_runner.py:52} INFO - Started process 273 to run task
[2023-07-25 21:45:24,619] {standard_task_runner.py:79} INFO - Running: ['***', 'tasks', 'run', 'dag_con_conexion_postgres', 'crear_tabla', 'scheduled__2023-07-23T00:00:00+00:00', '--job-id', '17', '--raw', '--subdir', 'DAGS_FOLDER/dag_etl_paises.py', '--cfg-path', '/tmp/tmpsj8xaaja', '--error-file', '/tmp/tmpf0p5wuc5']
[2023-07-25 21:45:24,628] {standard_task_runner.py:80} INFO - Job 17: Subtask crear_tabla
[2023-07-25 21:45:25,127] {task_command.py:371} INFO - Running <TaskInstance: dag_con_conexion_postgres.crear_tabla scheduled__2023-07-23T00:00:00+00:00 [running]> on host fef34475f162
[2023-07-25 21:45:25,689] {taskinstance.py:1591} INFO - Exporting the following env vars:
AIRFLOW_CTX_DAG_OWNER=Belenpintor
AIRFLOW_CTX_DAG_ID=dag_con_conexion_postgres
AIRFLOW_CTX_TASK_ID=crear_tabla
AIRFLOW_CTX_EXECUTION_DATE=2023-07-23T00:00:00+00:00
AIRFLOW_CTX_TRY_NUMBER=1
AIRFLOW_CTX_DAG_RUN_ID=scheduled__2023-07-23T00:00:00+00:00
[2023-07-25 21:45:25,692] {logging_mixin.py:115} INFO - creando conexion
[2023-07-25 21:45:25,741] {taskinstance.py:1909} ERROR - Task failed with exception
Traceback (most recent call last):
  File "/home/airflow/.local/lib/python3.7/site-packages/airflow/operators/python.py", line 171, in execute
    return_value = self.execute_callable()
  File "/home/airflow/.local/lib/python3.7/site-packages/airflow/operators/python.py", line 189, in execute_callable
    return self.python_callable(*self.op_args, **self.op_kwargs)
  File "/opt/airflow/dags/script_etl.py", line 38, in create_table
    connection = create_connection()
  File "/opt/airflow/dags/script_etl.py", line 15, in create_connection
    db_user = Variable.get("DB_USER")
  File "/home/airflow/.local/lib/python3.7/site-packages/airflow/models/variable.py", line 138, in get
    raise KeyError(f'Variable {key} does not exist')
KeyError: 'Variable DB_USER does not exist'
[2023-07-25 21:45:25,785] {taskinstance.py:1420} INFO - Marking task as FAILED. dag_id=dag_con_conexion_postgres, task_id=crear_tabla, execution_date=20230723T000000, start_date=20230725T214524, end_date=20230725T214525
[2023-07-25 21:45:25,890] {standard_task_runner.py:97} ERROR - Failed to execute job 17 for task crear_tabla ('Variable DB_USER does not exist'; 273)
[2023-07-25 21:45:25,973] {local_task_job.py:156} INFO - Task exited with return code 1
[2023-07-25 21:45:26,326] {local_task_job.py:273} INFO - 0 downstream tasks scheduled from follow-on schedule check
