[2023-07-26 23:56:40,013] {taskinstance.py:1179} INFO - Dependencies all met for <TaskInstance: dag_con_conexion_postgres.transformar_datos manual__2023-07-26T23:54:55.297911+00:00 [queued]>
[2023-07-26 23:56:40,038] {taskinstance.py:1179} INFO - Dependencies all met for <TaskInstance: dag_con_conexion_postgres.transformar_datos manual__2023-07-26T23:54:55.297911+00:00 [queued]>
[2023-07-26 23:56:40,042] {taskinstance.py:1376} INFO - 
--------------------------------------------------------------------------------
[2023-07-26 23:56:40,045] {taskinstance.py:1377} INFO - Starting attempt 1 of 1
[2023-07-26 23:56:40,047] {taskinstance.py:1378} INFO - 
--------------------------------------------------------------------------------
[2023-07-26 23:56:40,102] {taskinstance.py:1397} INFO - Executing <Task(PythonOperator): transformar_datos> on 2023-07-26 23:54:55.297911+00:00
[2023-07-26 23:56:40,122] {standard_task_runner.py:52} INFO - Started process 4990 to run task
[2023-07-26 23:56:40,142] {standard_task_runner.py:79} INFO - Running: ['***', 'tasks', 'run', 'dag_con_conexion_postgres', 'transformar_datos', 'manual__2023-07-26T23:54:55.297911+00:00', '--job-id', '136', '--raw', '--subdir', 'DAGS_FOLDER/dag_etl_paises.py', '--cfg-path', '/tmp/tmpykmkb20_', '--error-file', '/tmp/tmpbzj1_phj']
[2023-07-26 23:56:40,150] {standard_task_runner.py:80} INFO - Job 136: Subtask transformar_datos
[2023-07-26 23:56:40,273] {task_command.py:371} INFO - Running <TaskInstance: dag_con_conexion_postgres.transformar_datos manual__2023-07-26T23:54:55.297911+00:00 [running]> on host 484a5a9deba0
[2023-07-26 23:56:40,988] {taskinstance.py:1591} INFO - Exporting the following env vars:
AIRFLOW_CTX_DAG_OWNER=Belenpintor
AIRFLOW_CTX_DAG_ID=dag_con_conexion_postgres
AIRFLOW_CTX_TASK_ID=transformar_datos
AIRFLOW_CTX_EXECUTION_DATE=2023-07-26T23:54:55.297911+00:00
AIRFLOW_CTX_TRY_NUMBER=1
AIRFLOW_CTX_DAG_RUN_ID=manual__2023-07-26T23:54:55.297911+00:00
[2023-07-26 23:56:41,087] {logging_mixin.py:115} INFO - asi el dataframe nombre         Business Freedom  ...               process_date
ciudad_nombre                    ...                           
Aarhus                 9.940000  ... 2023-07-26 23:56:41.030597
Adelaide               9.399667  ... 2023-07-26 23:56:41.030597
Albuquerque            8.671000  ... 2023-07-26 23:56:41.030597
Almaty                 5.568000  ... 2023-07-26 23:56:41.030597
Amsterdam              8.836667  ... 2023-07-26 23:56:41.030597
...                         ...  ...                        ...
Winnipeg               8.966000  ... 2023-07-26 23:56:41.030597
Wroclaw                5.704333  ... 2023-07-26 23:56:41.030597
Yerevan                6.501000  ... 2023-07-26 23:56:41.030597
Zagreb                 5.720333  ... 2023-07-26 23:56:41.030597
Zurich                 8.888000  ... 2023-07-26 23:56:41.030597

[266 rows x 18 columns]
[2023-07-26 23:56:42,286] {logging_mixin.py:115} INFO - Values: [9.94, 6.31175, 4.015000000000001, 4.886500000000001, 5.3665, 7.633000000000001, 9.130666666666666, 6.1315, 8.373, 3.187, 4.13, 9.616500000000002, 2.827000000000001, 5.0680000000000005, 9.738500000000002, 3.5360000000000005, 2.5119999999999996, Timestamp('2023-07-26 23:56:41.030597')]
[2023-07-26 23:56:42,297] {logging_mixin.py:115} INFO - Index: Aarhus
[2023-07-26 23:56:42,318] {taskinstance.py:1909} ERROR - Task failed with exception
Traceback (most recent call last):
  File "/home/airflow/.local/lib/python3.7/site-packages/airflow/operators/python.py", line 171, in execute
    return_value = self.execute_callable()
  File "/home/airflow/.local/lib/python3.7/site-packages/airflow/operators/python.py", line 189, in execute_callable
    return self.python_callable(*self.op_args, **self.op_kwargs)
  File "/opt/airflow/dags/script_etl.py", line 90, in transform_data
    cursor.execute(insert_query, [index] + values)
IndexError: list index out of range
[2023-07-26 23:56:42,357] {taskinstance.py:1420} INFO - Marking task as FAILED. dag_id=dag_con_conexion_postgres, task_id=transformar_datos, execution_date=20230726T235455, start_date=20230726T235640, end_date=20230726T235642
[2023-07-26 23:56:42,400] {standard_task_runner.py:97} ERROR - Failed to execute job 136 for task transformar_datos (list index out of range; 4990)
[2023-07-26 23:56:42,477] {local_task_job.py:156} INFO - Task exited with return code 1
[2023-07-26 23:56:42,561] {local_task_job.py:273} INFO - 0 downstream tasks scheduled from follow-on schedule check
