[2023-07-12 05:29:47,402] {taskinstance.py:1179} INFO - Dependencies all met for <TaskInstance: dag_con_conexion_postgres.crear_tabla scheduled__2023-07-10T00:00:00+00:00 [queued]>
[2023-07-12 05:29:47,477] {taskinstance.py:1179} INFO - Dependencies all met for <TaskInstance: dag_con_conexion_postgres.crear_tabla scheduled__2023-07-10T00:00:00+00:00 [queued]>
[2023-07-12 05:29:47,479] {taskinstance.py:1376} INFO - 
--------------------------------------------------------------------------------
[2023-07-12 05:29:47,482] {taskinstance.py:1377} INFO - Starting attempt 1 of 1
[2023-07-12 05:29:47,487] {taskinstance.py:1378} INFO - 
--------------------------------------------------------------------------------
[2023-07-12 05:29:47,656] {taskinstance.py:1397} INFO - Executing <Task(PythonOperator): crear_tabla> on 2023-07-10 00:00:00+00:00
[2023-07-12 05:29:47,734] {standard_task_runner.py:52} INFO - Started process 419 to run task
[2023-07-12 05:29:47,822] {standard_task_runner.py:79} INFO - Running: ['***', 'tasks', 'run', 'dag_con_conexion_postgres', 'crear_tabla', 'scheduled__2023-07-10T00:00:00+00:00', '--job-id', '11', '--raw', '--subdir', 'DAGS_FOLDER/dag_etl_paises.py', '--cfg-path', '/tmp/tmpgzbzj405', '--error-file', '/tmp/tmpc5m0io73']
[2023-07-12 05:29:47,860] {standard_task_runner.py:80} INFO - Job 11: Subtask crear_tabla
[2023-07-12 05:29:48,799] {task_command.py:371} INFO - Running <TaskInstance: dag_con_conexion_postgres.crear_tabla scheduled__2023-07-10T00:00:00+00:00 [running]> on host 477ff5c75a8d
[2023-07-12 05:29:56,050] {taskinstance.py:1591} INFO - Exporting the following env vars:
AIRFLOW_CTX_DAG_OWNER=Belenpintor
AIRFLOW_CTX_DAG_ID=dag_con_conexion_postgres
AIRFLOW_CTX_TASK_ID=crear_tabla
AIRFLOW_CTX_EXECUTION_DATE=2023-07-10T00:00:00+00:00
AIRFLOW_CTX_TRY_NUMBER=1
AIRFLOW_CTX_DAG_RUN_ID=scheduled__2023-07-10T00:00:00+00:00
[2023-07-12 05:29:56,063] {taskinstance.py:1909} ERROR - Task failed with exception
Traceback (most recent call last):
  File "/home/airflow/.local/lib/python3.7/site-packages/airflow/operators/python.py", line 171, in execute
    return_value = self.execute_callable()
  File "/home/airflow/.local/lib/python3.7/site-packages/airflow/operators/python.py", line 189, in execute_callable
    return self.python_callable(*self.op_args, **self.op_kwargs)
  File "/opt/airflow/dags/script_etl.py", line 27, in create_table
    connection = create_connection()
  File "/opt/airflow/dags/script_etl.py", line 22, in create_connection
    database=db_database
  File "/home/airflow/.local/lib/python3.7/site-packages/psycopg2/__init__.py", line 122, in connect
    conn = _connect(dsn, connection_factory=connection_factory, **kwasync)
psycopg2.OperationalError: connection to server on socket "/var/run/postgresql/.s.PGSQL.5432" failed: No such file or directory
	Is the server running locally and accepting connections on that socket?

[2023-07-12 05:29:56,174] {taskinstance.py:1420} INFO - Marking task as FAILED. dag_id=dag_con_conexion_postgres, task_id=crear_tabla, execution_date=20230710T000000, start_date=20230712T052947, end_date=20230712T052956
[2023-07-12 05:29:56,319] {standard_task_runner.py:97} ERROR - Failed to execute job 11 for task crear_tabla (connection to server on socket "/var/run/postgresql/.s.PGSQL.5432" failed: No such file or directory
	Is the server running locally and accepting connections on that socket?
; 419)
[2023-07-12 05:29:56,439] {local_task_job.py:156} INFO - Task exited with return code 1
[2023-07-12 05:29:57,916] {local_task_job.py:273} INFO - 0 downstream tasks scheduled from follow-on schedule check
