[2023-07-12 05:29:47,402] {taskinstance.py:1179} INFO - Dependencies all met for <TaskInstance: dag_con_conexion_postgres.crear_tabla scheduled__2023-07-10T00:00:00+00:00 [queued]>
[2023-07-12 05:29:47,477] {taskinstance.py:1179} INFO - Dependencies all met for <TaskInstance: dag_con_conexion_postgres.crear_tabla scheduled__2023-07-10T00:00:00+00:00 [queued]>
[2023-07-12 05:29:47,479] {taskinstance.py:1376} INFO - 
--------------------------------------------------------------------------------
[2023-07-12 05:29:47,482] {taskinstance.py:1377} INFO - Starting attempt 1 of 1
[2023-07-12 05:29:47,487] {taskinstance.py:1378} INFO - 
--------------------------------------------------------------------------------
[2023-07-12 05:29:47,656] {taskinstance.py:1397} INFO - Executing <Task(PythonOperator): crear_tabla> on 2023-07-10 00:00:00+00:00
[2023-07-12 05:29:47,734] {standard_task_runner.py:52} INFO - Started process 419 to run task
[2023-07-12 05:29:47,822] {standard_task_runner.py:79} INFO - Running: ['***', 'tasks', 'run', 'dag_con_conexion_postgres', 'crear_tabla', 'scheduled__2023-07-10T00:00:00+00:00', '--job-id', '11', '--raw', '--subdir', 'DAGS_FOLDER/dag_etl_paises.py', '--cfg-path', '/tmp/tmpgzbzj405', '--error-file', '/tmp/tmpc5m0io73']
[2023-07-12 05:29:47,860] {standard_task_runner.py:80} INFO - Job 11: Subtask crear_tabla
[2023-07-12 05:29:48,799] {task_command.py:371} INFO - Running <TaskInstance: dag_con_conexion_postgres.crear_tabla scheduled__2023-07-10T00:00:00+00:00 [running]> on host 477ff5c75a8d
[2023-07-12 05:29:56,050] {taskinstance.py:1591} INFO - Exporting the following env vars:
AIRFLOW_CTX_DAG_OWNER=Belenpintor
AIRFLOW_CTX_DAG_ID=dag_con_conexion_postgres
AIRFLOW_CTX_TASK_ID=crear_tabla
AIRFLOW_CTX_EXECUTION_DATE=2023-07-10T00:00:00+00:00
AIRFLOW_CTX_TRY_NUMBER=1
AIRFLOW_CTX_DAG_RUN_ID=scheduled__2023-07-10T00:00:00+00:00
[2023-07-12 05:29:56,063] {taskinstance.py:1909} ERROR - Task failed with exception
Traceback (most recent call last):
  File "/home/airflow/.local/lib/python3.7/site-packages/airflow/operators/python.py", line 171, in execute
    return_value = self.execute_callable()
  File "/home/airflow/.local/lib/python3.7/site-packages/airflow/operators/python.py", line 189, in execute_callable
    return self.python_callable(*self.op_args, **self.op_kwargs)
  File "/opt/airflow/dags/script_etl.py", line 27, in create_table
    connection = create_connection()
  File "/opt/airflow/dags/script_etl.py", line 22, in create_connection
    database=db_database
  File "/home/airflow/.local/lib/python3.7/site-packages/psycopg2/__init__.py", line 122, in connect
    conn = _connect(dsn, connection_factory=connection_factory, **kwasync)
psycopg2.OperationalError: connection to server on socket "/var/run/postgresql/.s.PGSQL.5432" failed: No such file or directory
	Is the server running locally and accepting connections on that socket?

[2023-07-12 05:29:56,174] {taskinstance.py:1420} INFO - Marking task as FAILED. dag_id=dag_con_conexion_postgres, task_id=crear_tabla, execution_date=20230710T000000, start_date=20230712T052947, end_date=20230712T052956
[2023-07-12 05:29:56,319] {standard_task_runner.py:97} ERROR - Failed to execute job 11 for task crear_tabla (connection to server on socket "/var/run/postgresql/.s.PGSQL.5432" failed: No such file or directory
	Is the server running locally and accepting connections on that socket?
; 419)
[2023-07-12 05:29:56,439] {local_task_job.py:156} INFO - Task exited with return code 1
[2023-07-12 05:29:57,916] {local_task_job.py:273} INFO - 0 downstream tasks scheduled from follow-on schedule check
[2023-07-13 16:40:21,040] {taskinstance.py:1179} INFO - Dependencies all met for <TaskInstance: dag_con_conexion_postgres.crear_tabla scheduled__2023-07-10T00:00:00+00:00 [queued]>
[2023-07-13 16:40:21,432] {taskinstance.py:1179} INFO - Dependencies all met for <TaskInstance: dag_con_conexion_postgres.crear_tabla scheduled__2023-07-10T00:00:00+00:00 [queued]>
[2023-07-13 16:40:21,455] {taskinstance.py:1376} INFO - 
--------------------------------------------------------------------------------
[2023-07-13 16:40:21,543] {taskinstance.py:1377} INFO - Starting attempt 1 of 1
[2023-07-13 16:40:21,546] {taskinstance.py:1378} INFO - 
--------------------------------------------------------------------------------
[2023-07-13 16:40:22,008] {taskinstance.py:1397} INFO - Executing <Task(PythonOperator): crear_tabla> on 2023-07-10 00:00:00+00:00
[2023-07-13 16:40:22,054] {standard_task_runner.py:52} INFO - Started process 289 to run task
[2023-07-13 16:40:22,183] {standard_task_runner.py:79} INFO - Running: ['***', 'tasks', 'run', 'dag_con_conexion_postgres', 'crear_tabla', 'scheduled__2023-07-10T00:00:00+00:00', '--job-id', '23', '--raw', '--subdir', 'DAGS_FOLDER/dag_etl_paises.py', '--cfg-path', '/tmp/tmpy4q91axu', '--error-file', '/tmp/tmp1egyfihm']
[2023-07-13 16:40:22,199] {standard_task_runner.py:80} INFO - Job 23: Subtask crear_tabla
[2023-07-13 16:40:25,697] {task_command.py:371} INFO - Running <TaskInstance: dag_con_conexion_postgres.crear_tabla scheduled__2023-07-10T00:00:00+00:00 [running]> on host bd4a51b00e09
[2023-07-13 16:40:40,176] {taskinstance.py:1591} INFO - Exporting the following env vars:
AIRFLOW_CTX_DAG_OWNER=Belenpintor
AIRFLOW_CTX_DAG_ID=dag_con_conexion_postgres
AIRFLOW_CTX_TASK_ID=crear_tabla
AIRFLOW_CTX_EXECUTION_DATE=2023-07-10T00:00:00+00:00
AIRFLOW_CTX_TRY_NUMBER=1
AIRFLOW_CTX_DAG_RUN_ID=scheduled__2023-07-10T00:00:00+00:00
[2023-07-13 16:40:40,202] {logging_mixin.py:115} INFO - creando conexion
[2023-07-13 16:40:40,211] {script_etl.py:20} INFO - DB_USER probando usuario 1: None
[2023-07-13 16:40:40,219] {logging_mixin.py:115} INFO - usuario probando 1 None
[2023-07-13 16:40:40,240] {taskinstance.py:1909} ERROR - Task failed with exception
Traceback (most recent call last):
  File "/home/airflow/.local/lib/python3.7/site-packages/airflow/operators/python.py", line 171, in execute
    return_value = self.execute_callable()
  File "/home/airflow/.local/lib/python3.7/site-packages/airflow/operators/python.py", line 189, in execute_callable
    return self.python_callable(*self.op_args, **self.op_kwargs)
  File "/opt/airflow/dags/script_etl.py", line 34, in create_table
    connection = create_connection()
  File "/opt/airflow/dags/script_etl.py", line 29, in create_connection
    database=db_database
  File "/home/airflow/.local/lib/python3.7/site-packages/psycopg2/__init__.py", line 122, in connect
    conn = _connect(dsn, connection_factory=connection_factory, **kwasync)
psycopg2.OperationalError: connection to server on socket "/var/run/postgresql/.s.PGSQL.5432" failed: No such file or directory
	Is the server running locally and accepting connections on that socket?

[2023-07-13 16:40:41,084] {taskinstance.py:1420} INFO - Marking task as FAILED. dag_id=dag_con_conexion_postgres, task_id=crear_tabla, execution_date=20230710T000000, start_date=20230713T164021, end_date=20230713T164041
[2023-07-13 16:40:41,883] {standard_task_runner.py:97} ERROR - Failed to execute job 23 for task crear_tabla (connection to server on socket "/var/run/postgresql/.s.PGSQL.5432" failed: No such file or directory
	Is the server running locally and accepting connections on that socket?
; 289)
[2023-07-13 16:40:42,376] {local_task_job.py:156} INFO - Task exited with return code 1
[2023-07-13 16:40:43,319] {local_task_job.py:273} INFO - 0 downstream tasks scheduled from follow-on schedule check
[2023-07-13 16:58:55,771] {taskinstance.py:1179} INFO - Dependencies all met for <TaskInstance: dag_con_conexion_postgres.crear_tabla scheduled__2023-07-10T00:00:00+00:00 [queued]>
[2023-07-13 16:58:56,431] {taskinstance.py:1179} INFO - Dependencies all met for <TaskInstance: dag_con_conexion_postgres.crear_tabla scheduled__2023-07-10T00:00:00+00:00 [queued]>
[2023-07-13 16:58:56,440] {taskinstance.py:1376} INFO - 
--------------------------------------------------------------------------------
[2023-07-13 16:58:56,442] {taskinstance.py:1377} INFO - Starting attempt 1 of 1
[2023-07-13 16:58:56,453] {taskinstance.py:1378} INFO - 
--------------------------------------------------------------------------------
[2023-07-13 16:58:56,741] {taskinstance.py:1397} INFO - Executing <Task(PythonOperator): crear_tabla> on 2023-07-10 00:00:00+00:00
[2023-07-13 16:58:56,800] {standard_task_runner.py:52} INFO - Started process 811 to run task
[2023-07-13 16:58:56,872] {standard_task_runner.py:79} INFO - Running: ['***', 'tasks', 'run', 'dag_con_conexion_postgres', 'crear_tabla', 'scheduled__2023-07-10T00:00:00+00:00', '--job-id', '26', '--raw', '--subdir', 'DAGS_FOLDER/dag_etl_paises.py', '--cfg-path', '/tmp/tmpzssq1yhl', '--error-file', '/tmp/tmpsbduwpx6']
[2023-07-13 16:58:56,891] {standard_task_runner.py:80} INFO - Job 26: Subtask crear_tabla
[2023-07-13 16:58:58,634] {task_command.py:371} INFO - Running <TaskInstance: dag_con_conexion_postgres.crear_tabla scheduled__2023-07-10T00:00:00+00:00 [running]> on host bd4a51b00e09
[2023-07-13 16:59:27,827] {taskinstance.py:1591} INFO - Exporting the following env vars:
AIRFLOW_CTX_DAG_OWNER=Belenpintor
AIRFLOW_CTX_DAG_ID=dag_con_conexion_postgres
AIRFLOW_CTX_TASK_ID=crear_tabla
AIRFLOW_CTX_EXECUTION_DATE=2023-07-10T00:00:00+00:00
AIRFLOW_CTX_TRY_NUMBER=1
AIRFLOW_CTX_DAG_RUN_ID=scheduled__2023-07-10T00:00:00+00:00
[2023-07-13 16:59:27,831] {logging_mixin.py:115} INFO - creando conexion
[2023-07-13 16:59:28,582] {script_etl.py:20} INFO - DB_USER probando usuario 2: bapintor_coderhouse
[2023-07-13 16:59:28,586] {logging_mixin.py:115} INFO - usuario probando 2 bapintor_coderhouse
[2023-07-13 16:59:30,396] {python.py:173} INFO - Done. Returned value was: None
[2023-07-13 16:59:30,819] {taskinstance.py:1420} INFO - Marking task as SUCCESS. dag_id=dag_con_conexion_postgres, task_id=crear_tabla, execution_date=20230710T000000, start_date=20230713T165855, end_date=20230713T165930
[2023-07-13 16:59:31,323] {local_task_job.py:156} INFO - Task exited with return code 0
[2023-07-13 16:59:32,078] {local_task_job.py:273} INFO - 1 downstream tasks scheduled from follow-on schedule check
