[2023-07-27 00:02:08,903] {taskinstance.py:1179} INFO - Dependencies all met for <TaskInstance: dag_con_conexion_postgres.transformar_datos scheduled__2023-07-26T00:00:00+00:00 [queued]>
[2023-07-27 00:02:08,943] {taskinstance.py:1179} INFO - Dependencies all met for <TaskInstance: dag_con_conexion_postgres.transformar_datos scheduled__2023-07-26T00:00:00+00:00 [queued]>
[2023-07-27 00:02:08,945] {taskinstance.py:1376} INFO - 
--------------------------------------------------------------------------------
[2023-07-27 00:02:08,947] {taskinstance.py:1377} INFO - Starting attempt 1 of 1
[2023-07-27 00:02:08,949] {taskinstance.py:1378} INFO - 
--------------------------------------------------------------------------------
[2023-07-27 00:02:09,002] {taskinstance.py:1397} INFO - Executing <Task(PythonOperator): transformar_datos> on 2023-07-26 00:00:00+00:00
[2023-07-27 00:02:09,016] {standard_task_runner.py:52} INFO - Started process 5155 to run task
[2023-07-27 00:02:09,041] {standard_task_runner.py:79} INFO - Running: ['***', 'tasks', 'run', 'dag_con_conexion_postgres', 'transformar_datos', 'scheduled__2023-07-26T00:00:00+00:00', '--job-id', '139', '--raw', '--subdir', 'DAGS_FOLDER/dag_etl_paises.py', '--cfg-path', '/tmp/tmpiu8dw31t', '--error-file', '/tmp/tmpt5l7uvj7']
[2023-07-27 00:02:09,051] {standard_task_runner.py:80} INFO - Job 139: Subtask transformar_datos
[2023-07-27 00:02:09,485] {task_command.py:371} INFO - Running <TaskInstance: dag_con_conexion_postgres.transformar_datos scheduled__2023-07-26T00:00:00+00:00 [running]> on host 484a5a9deba0
[2023-07-27 00:02:10,304] {taskinstance.py:1591} INFO - Exporting the following env vars:
AIRFLOW_CTX_DAG_OWNER=Belenpintor
AIRFLOW_CTX_DAG_ID=dag_con_conexion_postgres
AIRFLOW_CTX_TASK_ID=transformar_datos
AIRFLOW_CTX_EXECUTION_DATE=2023-07-26T00:00:00+00:00
AIRFLOW_CTX_TRY_NUMBER=1
AIRFLOW_CTX_DAG_RUN_ID=scheduled__2023-07-26T00:00:00+00:00
[2023-07-27 00:02:10,991] {logging_mixin.py:115} INFO - asi el dataframe nombre         Business Freedom  ...               process_date
ciudad_nombre                    ...                           
Aarhus                 9.940000  ... 2023-07-27 00:02:10.550703
Adelaide               9.399667  ... 2023-07-27 00:02:10.550703
Albuquerque            8.671000  ... 2023-07-27 00:02:10.550703
Almaty                 5.568000  ... 2023-07-27 00:02:10.550703
Amsterdam              8.836667  ... 2023-07-27 00:02:10.550703
...                         ...  ...                        ...
Winnipeg               8.966000  ... 2023-07-27 00:02:10.550703
Wroclaw                5.704333  ... 2023-07-27 00:02:10.550703
Yerevan                6.501000  ... 2023-07-27 00:02:10.550703
Zagreb                 5.720333  ... 2023-07-27 00:02:10.550703
Zurich                 8.888000  ... 2023-07-27 00:02:10.550703

[266 rows x 18 columns]
[2023-07-27 00:02:12,391] {taskinstance.py:1909} ERROR - Task failed with exception
Traceback (most recent call last):
  File "/home/airflow/.local/lib/python3.7/site-packages/airflow/operators/python.py", line 171, in execute
    return_value = self.execute_callable()
  File "/home/airflow/.local/lib/python3.7/site-packages/airflow/operators/python.py", line 189, in execute_callable
    return self.python_callable(*self.op_args, **self.op_kwargs)
  File "/opt/airflow/dags/script_etl.py", line 117, in transform_data
    cursor.execute(insert_query_with_columns, [index] + values + [datetime.utcnow()])
IndexError: list index out of range
[2023-07-27 00:02:12,472] {taskinstance.py:1420} INFO - Marking task as FAILED. dag_id=dag_con_conexion_postgres, task_id=transformar_datos, execution_date=20230726T000000, start_date=20230727T000208, end_date=20230727T000212
[2023-07-27 00:02:12,596] {standard_task_runner.py:97} ERROR - Failed to execute job 139 for task transformar_datos (list index out of range; 5155)
[2023-07-27 00:02:12,684] {local_task_job.py:156} INFO - Task exited with return code 1
[2023-07-27 00:02:13,436] {local_task_job.py:273} INFO - 0 downstream tasks scheduled from follow-on schedule check
