[2023-07-28 23:31:55,440] {taskinstance.py:1179} INFO - Dependencies all met for <TaskInstance: dag_etl_paises.dag_envio_success manual__2023-07-28T23:26:40.613382+00:00 [queued]>
[2023-07-28 23:31:55,507] {taskinstance.py:1179} INFO - Dependencies all met for <TaskInstance: dag_etl_paises.dag_envio_success manual__2023-07-28T23:26:40.613382+00:00 [queued]>
[2023-07-28 23:31:55,509] {taskinstance.py:1376} INFO - 
--------------------------------------------------------------------------------
[2023-07-28 23:31:55,513] {taskinstance.py:1377} INFO - Starting attempt 2 of 2
[2023-07-28 23:31:55,515] {taskinstance.py:1378} INFO - 
--------------------------------------------------------------------------------
[2023-07-28 23:31:55,612] {taskinstance.py:1397} INFO - Executing <Task(PythonOperator): dag_envio_success> on 2023-07-28 23:26:40.613382+00:00
[2023-07-28 23:31:55,635] {standard_task_runner.py:52} INFO - Started process 1400 to run task
[2023-07-28 23:31:55,662] {standard_task_runner.py:79} INFO - Running: ['***', 'tasks', 'run', 'dag_etl_paises', 'dag_envio_success', 'manual__2023-07-28T23:26:40.613382+00:00', '--job-id', '39', '--raw', '--subdir', 'DAGS_FOLDER/dag_etl_paises.py', '--cfg-path', '/tmp/tmpwfih1rwe', '--error-file', '/tmp/tmpn79b83me']
[2023-07-28 23:31:55,674] {standard_task_runner.py:80} INFO - Job 39: Subtask dag_envio_success
[2023-07-28 23:31:55,951] {task_command.py:371} INFO - Running <TaskInstance: dag_etl_paises.dag_envio_success manual__2023-07-28T23:26:40.613382+00:00 [running]> on host 068a3bc06d1c
[2023-07-28 23:31:56,208] {taskinstance.py:1591} INFO - Exporting the following env vars:
AIRFLOW_CTX_DAG_OWNER=Belenpintor
AIRFLOW_CTX_DAG_ID=dag_etl_paises
AIRFLOW_CTX_TASK_ID=dag_envio_success
AIRFLOW_CTX_EXECUTION_DATE=2023-07-28T23:26:40.613382+00:00
AIRFLOW_CTX_TRY_NUMBER=2
AIRFLOW_CTX_DAG_RUN_ID=manual__2023-07-28T23:26:40.613382+00:00
[2023-07-28 23:31:56,253] {logging_mixin.py:115} INFO - [Errno -2] Name or service not known
[2023-07-28 23:31:56,255] {logging_mixin.py:115} INFO - Failure
[2023-07-28 23:31:56,257] {taskinstance.py:1909} ERROR - Task failed with exception
Traceback (most recent call last):
  File "/home/airflow/.local/lib/python3.7/site-packages/airflow/operators/python.py", line 171, in execute
    return_value = self.execute_callable()
  File "/home/airflow/.local/lib/python3.7/site-packages/airflow/operators/python.py", line 189, in execute_callable
    return self.python_callable(*self.op_args, **self.op_kwargs)
  File "/opt/airflow/dags/script_etl.py", line 150, in enviar_success
    raise exception
  File "/opt/airflow/dags/script_etl.py", line 139, in enviar_success
    x=smtplib.SMTP(Variable.get("SMTP_HOST"),Variable.get("SMTP_PORT"))
  File "/usr/local/lib/python3.7/smtplib.py", line 251, in __init__
    (code, msg) = self.connect(host, port)
  File "/usr/local/lib/python3.7/smtplib.py", line 336, in connect
    self.sock = self._get_socket(host, port, self.timeout)
  File "/usr/local/lib/python3.7/smtplib.py", line 307, in _get_socket
    self.source_address)
  File "/usr/local/lib/python3.7/socket.py", line 707, in create_connection
    for res in getaddrinfo(host, port, 0, SOCK_STREAM):
  File "/usr/local/lib/python3.7/socket.py", line 752, in getaddrinfo
    for res in _socket.getaddrinfo(host, port, family, type, proto, flags):
socket.gaierror: [Errno -2] Name or service not known
[2023-07-28 23:31:56,281] {taskinstance.py:1420} INFO - Marking task as FAILED. dag_id=dag_etl_paises, task_id=dag_envio_success, execution_date=20230728T232640, start_date=20230728T233155, end_date=20230728T233156
[2023-07-28 23:31:56,318] {standard_task_runner.py:97} ERROR - Failed to execute job 39 for task dag_envio_success ([Errno -2] Name or service not known; 1400)
[2023-07-28 23:31:56,353] {local_task_job.py:156} INFO - Task exited with return code 1
[2023-07-28 23:31:56,458] {local_task_job.py:273} INFO - 0 downstream tasks scheduled from follow-on schedule check
