[2023-07-26 23:31:28,648] {taskinstance.py:1179} INFO - Dependencies all met for <TaskInstance: dag_con_conexion_postgres.transformar_datos manual__2023-07-26T23:29:44.392475+00:00 [queued]>
[2023-07-26 23:31:28,668] {taskinstance.py:1179} INFO - Dependencies all met for <TaskInstance: dag_con_conexion_postgres.transformar_datos manual__2023-07-26T23:29:44.392475+00:00 [queued]>
[2023-07-26 23:31:28,670] {taskinstance.py:1376} INFO - 
--------------------------------------------------------------------------------
[2023-07-26 23:31:28,672] {taskinstance.py:1377} INFO - Starting attempt 1 of 1
[2023-07-26 23:31:28,675] {taskinstance.py:1378} INFO - 
--------------------------------------------------------------------------------
[2023-07-26 23:31:28,718] {taskinstance.py:1397} INFO - Executing <Task(PythonOperator): transformar_datos> on 2023-07-26 23:29:44.392475+00:00
[2023-07-26 23:31:28,728] {standard_task_runner.py:52} INFO - Started process 4190 to run task
[2023-07-26 23:31:28,740] {standard_task_runner.py:79} INFO - Running: ['***', 'tasks', 'run', 'dag_con_conexion_postgres', 'transformar_datos', 'manual__2023-07-26T23:29:44.392475+00:00', '--job-id', '124', '--raw', '--subdir', 'DAGS_FOLDER/dag_etl_paises.py', '--cfg-path', '/tmp/tmpsjj5jgrw', '--error-file', '/tmp/tmpkrsmqf56']
[2023-07-26 23:31:28,744] {standard_task_runner.py:80} INFO - Job 124: Subtask transformar_datos
[2023-07-26 23:31:28,867] {task_command.py:371} INFO - Running <TaskInstance: dag_con_conexion_postgres.transformar_datos manual__2023-07-26T23:29:44.392475+00:00 [running]> on host 484a5a9deba0
[2023-07-26 23:31:29,263] {taskinstance.py:1591} INFO - Exporting the following env vars:
AIRFLOW_CTX_DAG_OWNER=Belenpintor
AIRFLOW_CTX_DAG_ID=dag_con_conexion_postgres
AIRFLOW_CTX_TASK_ID=transformar_datos
AIRFLOW_CTX_EXECUTION_DATE=2023-07-26T23:29:44.392475+00:00
AIRFLOW_CTX_TRY_NUMBER=1
AIRFLOW_CTX_DAG_RUN_ID=manual__2023-07-26T23:29:44.392475+00:00
[2023-07-26 23:31:29,268] {taskinstance.py:1909} ERROR - Task failed with exception
Traceback (most recent call last):
  File "/home/airflow/.local/lib/python3.7/site-packages/airflow/operators/python.py", line 171, in execute
    return_value = self.execute_callable()
  File "/home/airflow/.local/lib/python3.7/site-packages/airflow/operators/python.py", line 189, in execute_callable
    return self.python_callable(*self.op_args, **self.op_kwargs)
  File "/opt/airflow/dags/script_etl.py", line 63, in transform_data
    for ciudad_nombre,ciudad in ciudades_data.items():
AttributeError: 'list' object has no attribute 'items'
[2023-07-26 23:31:29,300] {taskinstance.py:1420} INFO - Marking task as FAILED. dag_id=dag_con_conexion_postgres, task_id=transformar_datos, execution_date=20230726T232944, start_date=20230726T233128, end_date=20230726T233129
[2023-07-26 23:31:29,352] {standard_task_runner.py:97} ERROR - Failed to execute job 124 for task transformar_datos ('list' object has no attribute 'items'; 4190)
[2023-07-26 23:31:29,420] {local_task_job.py:156} INFO - Task exited with return code 1
[2023-07-26 23:31:29,763] {local_task_job.py:273} INFO - 0 downstream tasks scheduled from follow-on schedule check
