[2023-07-29 02:14:55,957] {taskinstance.py:1179} INFO - Dependencies all met for <TaskInstance: dag_etl_paises.verificar_threshold manual__2023-07-29T02:10:54.739595+00:00 [queued]>
[2023-07-29 02:14:55,975] {taskinstance.py:1179} INFO - Dependencies all met for <TaskInstance: dag_etl_paises.verificar_threshold manual__2023-07-29T02:10:54.739595+00:00 [queued]>
[2023-07-29 02:14:55,977] {taskinstance.py:1376} INFO - 
--------------------------------------------------------------------------------
[2023-07-29 02:14:55,979] {taskinstance.py:1377} INFO - Starting attempt 1 of 2
[2023-07-29 02:14:55,981] {taskinstance.py:1378} INFO - 
--------------------------------------------------------------------------------
[2023-07-29 02:14:56,007] {taskinstance.py:1397} INFO - Executing <Task(PythonOperator): verificar_threshold> on 2023-07-29 02:10:54.739595+00:00
[2023-07-29 02:14:56,014] {standard_task_runner.py:52} INFO - Started process 3754 to run task
[2023-07-29 02:14:56,025] {standard_task_runner.py:79} INFO - Running: ['***', 'tasks', 'run', 'dag_etl_paises', 'verificar_threshold', 'manual__2023-07-29T02:10:54.739595+00:00', '--job-id', '81', '--raw', '--subdir', 'DAGS_FOLDER/dag_etl_paises.py', '--cfg-path', '/tmp/tmp6np6ze5h', '--error-file', '/tmp/tmp4d1txo0u']
[2023-07-29 02:14:56,028] {standard_task_runner.py:80} INFO - Job 81: Subtask verificar_threshold
[2023-07-29 02:14:56,152] {task_command.py:371} INFO - Running <TaskInstance: dag_etl_paises.verificar_threshold manual__2023-07-29T02:10:54.739595+00:00 [running]> on host 068a3bc06d1c
[2023-07-29 02:14:56,434] {taskinstance.py:1591} INFO - Exporting the following env vars:
AIRFLOW_CTX_DAG_OWNER=Belenpintor
AIRFLOW_CTX_DAG_ID=dag_etl_paises
AIRFLOW_CTX_TASK_ID=verificar_threshold
AIRFLOW_CTX_EXECUTION_DATE=2023-07-29T02:10:54.739595+00:00
AIRFLOW_CTX_TRY_NUMBER=1
AIRFLOW_CTX_DAG_RUN_ID=manual__2023-07-29T02:10:54.739595+00:00
[2023-07-29 02:14:56,479] {base.py:68} INFO - Using connection ID 'redshift_belen' for task execution.
[2023-07-29 02:14:57,639] {taskinstance.py:1909} ERROR - Task failed with exception
Traceback (most recent call last):
  File "/home/airflow/.local/lib/python3.7/site-packages/airflow/operators/python.py", line 171, in execute
    return_value = self.execute_callable()
  File "/home/airflow/.local/lib/python3.7/site-packages/airflow/operators/python.py", line 189, in execute_callable
    return self.python_callable(*self.op_args, **self.op_kwargs)
  File "/opt/airflow/dags/dag_etl_paises.py", line 44, in verificar_threshold
    with open('ruta_del_archivo_config.json', 'r') as json_config:
FileNotFoundError: [Errno 2] No such file or directory: 'ruta_del_archivo_config.json'
[2023-07-29 02:14:57,664] {taskinstance.py:1420} INFO - Marking task as UP_FOR_RETRY. dag_id=dag_etl_paises, task_id=verificar_threshold, execution_date=20230729T021054, start_date=20230729T021455, end_date=20230729T021457
[2023-07-29 02:14:57,688] {standard_task_runner.py:97} ERROR - Failed to execute job 81 for task verificar_threshold ([Errno 2] No such file or directory: 'ruta_del_archivo_config.json'; 3754)
[2023-07-29 02:14:57,728] {local_task_job.py:156} INFO - Task exited with return code 1
[2023-07-29 02:14:57,835] {local_task_job.py:273} INFO - 0 downstream tasks scheduled from follow-on schedule check
