[2023-07-26 23:26:12,103] {taskinstance.py:1179} INFO - Dependencies all met for <TaskInstance: dag_con_conexion_postgres.transformar_datos manual__2023-07-26T23:24:26.654557+00:00 [queued]>
[2023-07-26 23:26:12,123] {taskinstance.py:1179} INFO - Dependencies all met for <TaskInstance: dag_con_conexion_postgres.transformar_datos manual__2023-07-26T23:24:26.654557+00:00 [queued]>
[2023-07-26 23:26:12,125] {taskinstance.py:1376} INFO - 
--------------------------------------------------------------------------------
[2023-07-26 23:26:12,128] {taskinstance.py:1377} INFO - Starting attempt 1 of 1
[2023-07-26 23:26:12,130] {taskinstance.py:1378} INFO - 
--------------------------------------------------------------------------------
[2023-07-26 23:26:12,158] {taskinstance.py:1397} INFO - Executing <Task(PythonOperator): transformar_datos> on 2023-07-26 23:24:26.654557+00:00
[2023-07-26 23:26:12,166] {standard_task_runner.py:52} INFO - Started process 4019 to run task
[2023-07-26 23:26:12,182] {standard_task_runner.py:79} INFO - Running: ['***', 'tasks', 'run', 'dag_con_conexion_postgres', 'transformar_datos', 'manual__2023-07-26T23:24:26.654557+00:00', '--job-id', '121', '--raw', '--subdir', 'DAGS_FOLDER/dag_etl_paises.py', '--cfg-path', '/tmp/tmpjzlrafx9', '--error-file', '/tmp/tmpto04cnds']
[2023-07-26 23:26:12,188] {standard_task_runner.py:80} INFO - Job 121: Subtask transformar_datos
[2023-07-26 23:26:12,394] {task_command.py:371} INFO - Running <TaskInstance: dag_con_conexion_postgres.transformar_datos manual__2023-07-26T23:24:26.654557+00:00 [running]> on host 484a5a9deba0
[2023-07-26 23:26:12,657] {taskinstance.py:1591} INFO - Exporting the following env vars:
AIRFLOW_CTX_DAG_OWNER=Belenpintor
AIRFLOW_CTX_DAG_ID=dag_con_conexion_postgres
AIRFLOW_CTX_TASK_ID=transformar_datos
AIRFLOW_CTX_EXECUTION_DATE=2023-07-26T23:24:26.654557+00:00
AIRFLOW_CTX_TRY_NUMBER=1
AIRFLOW_CTX_DAG_RUN_ID=manual__2023-07-26T23:24:26.654557+00:00
[2023-07-26 23:26:12,664] {taskinstance.py:1909} ERROR - Task failed with exception
Traceback (most recent call last):
  File "/home/airflow/.local/lib/python3.7/site-packages/airflow/operators/python.py", line 171, in execute
    return_value = self.execute_callable()
  File "/home/airflow/.local/lib/python3.7/site-packages/airflow/operators/python.py", line 189, in execute_callable
    return self.python_callable(*self.op_args, **self.op_kwargs)
  File "/opt/airflow/dags/script_etl.py", line 64, in transform_data
    ciudad_nombre=dupla.key()
AttributeError: 'dict' object has no attribute 'key'
[2023-07-26 23:26:12,689] {taskinstance.py:1420} INFO - Marking task as FAILED. dag_id=dag_con_conexion_postgres, task_id=transformar_datos, execution_date=20230726T232426, start_date=20230726T232612, end_date=20230726T232612
[2023-07-26 23:26:12,712] {standard_task_runner.py:97} ERROR - Failed to execute job 121 for task transformar_datos ('dict' object has no attribute 'key'; 4019)
[2023-07-26 23:26:12,764] {local_task_job.py:156} INFO - Task exited with return code 1
[2023-07-26 23:26:12,819] {local_task_job.py:273} INFO - 0 downstream tasks scheduled from follow-on schedule check
