[2023-07-25 21:45:14,559] {taskinstance.py:1179} INFO - Dependencies all met for <TaskInstance: dag_con_conexion_postgres.crear_tabla scheduled__2023-07-20T00:00:00+00:00 [queued]>
[2023-07-25 21:45:14,665] {taskinstance.py:1179} INFO - Dependencies all met for <TaskInstance: dag_con_conexion_postgres.crear_tabla scheduled__2023-07-20T00:00:00+00:00 [queued]>
[2023-07-25 21:45:14,668] {taskinstance.py:1376} INFO - 
--------------------------------------------------------------------------------
[2023-07-25 21:45:14,671] {taskinstance.py:1377} INFO - Starting attempt 1 of 1
[2023-07-25 21:45:14,681] {taskinstance.py:1378} INFO - 
--------------------------------------------------------------------------------
[2023-07-25 21:45:14,822] {taskinstance.py:1397} INFO - Executing <Task(PythonOperator): crear_tabla> on 2023-07-20 00:00:00+00:00
[2023-07-25 21:45:14,840] {standard_task_runner.py:52} INFO - Started process 261 to run task
[2023-07-25 21:45:14,872] {standard_task_runner.py:79} INFO - Running: ['***', 'tasks', 'run', 'dag_con_conexion_postgres', 'crear_tabla', 'scheduled__2023-07-20T00:00:00+00:00', '--job-id', '14', '--raw', '--subdir', 'DAGS_FOLDER/dag_etl_paises.py', '--cfg-path', '/tmp/tmpl29zzbmp', '--error-file', '/tmp/tmppktnhtrq']
[2023-07-25 21:45:14,880] {standard_task_runner.py:80} INFO - Job 14: Subtask crear_tabla
[2023-07-25 21:45:15,231] {task_command.py:371} INFO - Running <TaskInstance: dag_con_conexion_postgres.crear_tabla scheduled__2023-07-20T00:00:00+00:00 [running]> on host fef34475f162
[2023-07-25 21:45:15,604] {taskinstance.py:1591} INFO - Exporting the following env vars:
AIRFLOW_CTX_DAG_OWNER=Belenpintor
AIRFLOW_CTX_DAG_ID=dag_con_conexion_postgres
AIRFLOW_CTX_TASK_ID=crear_tabla
AIRFLOW_CTX_EXECUTION_DATE=2023-07-20T00:00:00+00:00
AIRFLOW_CTX_TRY_NUMBER=1
AIRFLOW_CTX_DAG_RUN_ID=scheduled__2023-07-20T00:00:00+00:00
[2023-07-25 21:45:15,607] {logging_mixin.py:115} INFO - creando conexion
[2023-07-25 21:45:15,631] {taskinstance.py:1909} ERROR - Task failed with exception
Traceback (most recent call last):
  File "/home/airflow/.local/lib/python3.7/site-packages/airflow/operators/python.py", line 171, in execute
    return_value = self.execute_callable()
  File "/home/airflow/.local/lib/python3.7/site-packages/airflow/operators/python.py", line 189, in execute_callable
    return self.python_callable(*self.op_args, **self.op_kwargs)
  File "/opt/airflow/dags/script_etl.py", line 38, in create_table
    connection = create_connection()
  File "/opt/airflow/dags/script_etl.py", line 15, in create_connection
    db_user = Variable.get("DB_USER")
  File "/home/airflow/.local/lib/python3.7/site-packages/airflow/models/variable.py", line 138, in get
    raise KeyError(f'Variable {key} does not exist')
KeyError: 'Variable DB_USER does not exist'
[2023-07-25 21:45:15,656] {taskinstance.py:1420} INFO - Marking task as FAILED. dag_id=dag_con_conexion_postgres, task_id=crear_tabla, execution_date=20230720T000000, start_date=20230725T214514, end_date=20230725T214515
[2023-07-25 21:45:15,695] {standard_task_runner.py:97} ERROR - Failed to execute job 14 for task crear_tabla ('Variable DB_USER does not exist'; 261)
[2023-07-25 21:45:15,748] {local_task_job.py:156} INFO - Task exited with return code 1
[2023-07-25 21:45:15,852] {local_task_job.py:273} INFO - 0 downstream tasks scheduled from follow-on schedule check
