[2023-07-25 21:45:20,050] {taskinstance.py:1179} INFO - Dependencies all met for <TaskInstance: dag_con_conexion_postgres.crear_tabla scheduled__2023-07-21T00:00:00+00:00 [queued]>
[2023-07-25 21:45:20,097] {taskinstance.py:1179} INFO - Dependencies all met for <TaskInstance: dag_con_conexion_postgres.crear_tabla scheduled__2023-07-21T00:00:00+00:00 [queued]>
[2023-07-25 21:45:20,104] {taskinstance.py:1376} INFO - 
--------------------------------------------------------------------------------
[2023-07-25 21:45:20,108] {taskinstance.py:1377} INFO - Starting attempt 1 of 1
[2023-07-25 21:45:20,113] {taskinstance.py:1378} INFO - 
--------------------------------------------------------------------------------
[2023-07-25 21:45:20,360] {taskinstance.py:1397} INFO - Executing <Task(PythonOperator): crear_tabla> on 2023-07-21 00:00:00+00:00
[2023-07-25 21:45:20,457] {standard_task_runner.py:52} INFO - Started process 269 to run task
[2023-07-25 21:45:20,482] {standard_task_runner.py:79} INFO - Running: ['***', 'tasks', 'run', 'dag_con_conexion_postgres', 'crear_tabla', 'scheduled__2023-07-21T00:00:00+00:00', '--job-id', '15', '--raw', '--subdir', 'DAGS_FOLDER/dag_etl_paises.py', '--cfg-path', '/tmp/tmpc8pim888', '--error-file', '/tmp/tmpyozzud9z']
[2023-07-25 21:45:20,494] {standard_task_runner.py:80} INFO - Job 15: Subtask crear_tabla
[2023-07-25 21:45:21,494] {task_command.py:371} INFO - Running <TaskInstance: dag_con_conexion_postgres.crear_tabla scheduled__2023-07-21T00:00:00+00:00 [running]> on host fef34475f162
[2023-07-25 21:45:22,689] {taskinstance.py:1591} INFO - Exporting the following env vars:
AIRFLOW_CTX_DAG_OWNER=Belenpintor
AIRFLOW_CTX_DAG_ID=dag_con_conexion_postgres
AIRFLOW_CTX_TASK_ID=crear_tabla
AIRFLOW_CTX_EXECUTION_DATE=2023-07-21T00:00:00+00:00
AIRFLOW_CTX_TRY_NUMBER=1
AIRFLOW_CTX_DAG_RUN_ID=scheduled__2023-07-21T00:00:00+00:00
[2023-07-25 21:45:22,697] {logging_mixin.py:115} INFO - creando conexion
[2023-07-25 21:45:22,790] {taskinstance.py:1909} ERROR - Task failed with exception
Traceback (most recent call last):
  File "/home/airflow/.local/lib/python3.7/site-packages/airflow/operators/python.py", line 171, in execute
    return_value = self.execute_callable()
  File "/home/airflow/.local/lib/python3.7/site-packages/airflow/operators/python.py", line 189, in execute_callable
    return self.python_callable(*self.op_args, **self.op_kwargs)
  File "/opt/airflow/dags/script_etl.py", line 38, in create_table
    connection = create_connection()
  File "/opt/airflow/dags/script_etl.py", line 15, in create_connection
    db_user = Variable.get("DB_USER")
  File "/home/airflow/.local/lib/python3.7/site-packages/airflow/models/variable.py", line 138, in get
    raise KeyError(f'Variable {key} does not exist')
KeyError: 'Variable DB_USER does not exist'
[2023-07-25 21:45:22,888] {taskinstance.py:1420} INFO - Marking task as FAILED. dag_id=dag_con_conexion_postgres, task_id=crear_tabla, execution_date=20230721T000000, start_date=20230725T214520, end_date=20230725T214522
[2023-07-25 21:45:23,042] {standard_task_runner.py:97} ERROR - Failed to execute job 15 for task crear_tabla ('Variable DB_USER does not exist'; 269)
[2023-07-25 21:45:23,135] {local_task_job.py:156} INFO - Task exited with return code 1
[2023-07-25 21:45:23,613] {local_task_job.py:273} INFO - 0 downstream tasks scheduled from follow-on schedule check
